Workbook

Sheet tot_cost
A1: 1 | B1: 2
A2: 152800.64 | B2: 152312.56

Sheet C_strg_agg
A1: 1 | B1: 2
A2: 1615358 | B2: 970888.98
A3: =A2/2000000 -> 0.80767899 | B3: =B2/2000000 -> 0.48544449 | C3: =C2/2000000 -> 0 | D3: =D2/2000000 -> 0 | E3: =E2/2000000 -> 0 | F3: =F2/2000000 -> 0 | G3: =G2/2000000 -> 0 | H3: =H2/2000000 -> 0 | ... CV3: =CV2/2000000 -> 0

Sheet storage_max
A1: 1 | B1: 2
A2: 2996763.4 | B2: 970888.98

Sheet eltoH2
B1: 2010 | C1: 2010 | D1: 2020 | E1: 2020 | F1: 2030 | G1: 2030 | H1: 2040 | I1: 2040 | J1: 2050 | K1: 2050 | L1: 2060 | M1: 2060 | N1: 2070 | O1: 2070 | P1: 2080 | Q1: 2080 | R1: 2090 | S1: 2090 | T1: 2100 | U1: 2100 | V1: 2110 | W1: 2110 | X1: 2120 | Y1: 2120 | Z1: 2130 | AA1: 2130 | AB1: 2140 | AC1: 2140 | AD1: 2150 | AE1: 2150
B2: 1 | C2: 2 | D2: 1 | E2: 2 | F2: 1 | G2: 2 | H2: 1 | I2: 2 | J2: 1 | K2: 2 | L2: 1 | M2: 2 | N2: 1 | O2: 2 | P2: 1 | Q2: 2 | R2: 1 | S2: 2 | T2: 1 | U2: 2 | V2: 1 | W2: 2 | X2: 1 | Y2: 2 | Z2: 1 | AA2: 2 | AB2: 1 | AC2: 2 | AD2: 1 | AE2: 2
A3: EUR | B3: 2.0811933e-10 | C3: 1.4125676e-10 | D3: 3.1697481e-10 | E3: 2.0892639e-10 | F3: 6.878457e-10 | G3: 4.5730664e-10 | H3: 1.1003305e-09 | I3: 6.5899209e-10 | J3: 7.807204e-09 | K3: 4.8228491e-09 | L3: 0.077216586 | M3: 1.8501371e-08 | N3: 0.62941781 | O3: 0.006893299 | P3: 1.2187744 | Q3: 0.10729233 | R3: 2.8091229 | S3: 0.93511759 | T3: 3.9706401 | U3: 1.2362123 | V3: 1.6379027 | W3: 0.66700948 | X3: 1.7267618 | Y3: 0.63453083 | Z3: 1.2229438 | AA3: 1.4244246 | AB3: 1.0178609 | AC3: 4.1510161 | AD3: 0.64043613 | AE3: 4.3569302
A4: NAM | B4: 3.8899348e-10 | C4: 2.6407487e-10 | D4: 0.060366846 | E4: 0.053409372 | F4: 1.1762238e-09 | G4: 7.8703277e-10 | H4: 0.010880023 | I4: 9.6144463e-10 | J4: 6.0576052e-09 | K4: 1.4210935e-08 | L4: 0.098798372 | M4: 0.086222845 | N4: 0.79790904 | O4: 0.58253448 | P4: 1.8128346 | Q4: 1.0334057 | R4: 5.2233173 | S4: 1.8370378 | T4: 10.478015 | U4: 5.5682681 | V4: 6.4113372 | W4: 4.0945497 | X4: 4.2905621 | Y4: 4.9545751 | Z4: 3.0381589 | AA4: 8.3854378 | AB4: 2.0637916 | AC4: 9.0307278 | AD4: 1.3143656 | AE4: 8.8011752
A5: PAO | B5: 1.4779144e-10 | C5: 1.0063401e-10 | D5: 1.1295346e-10 | E5: 7.9787618e-11 | F5: 5.5806246e-10 | G5: 3.3454277e-10 | H5: 0.00055812947 | I5: 9.4421243e-10 | J5: 8.8347838e-09 | K5: 6.098083e-09 | L5: 0.72083143 | M5: 0.010495824 | N5: 2.3275076 | O5: 0.13085024 | P5: 3.8242216 | Q5: 0.86591781 | R5: 6.4780989 | S5: 1.3383064 | T5: 8.680224 | U5: 3.9117204 | V5: 5.2266897 | W5: 2.5428175 | X5: 3.9836376 | Y5: 2.5276435 | Z5: 3.7478924 | AA5: 6.1190074 | AB5: 3.9424904 | AC5: 7.3187667 | AD5: 3.2055673 | AE5: 7.264333
A6: FSU | B6: 2.127868e-10 | C6: 1.439563e-10 | D6: 2.4680807e-10 | E6: 1.6849443e-10 | F6: 8.2001747e-10 | G6: 5.0955925e-10 | H6: 1.8807543e-09 | I6: 1.1712606e-09 | J6: 3.5645561e-09 | K6: 3.0700729e-09 | L6: 0.00054026313 | M6: 9.0671197e-09 | N6: 0.097420151 | O6: 1.9466502e-08 | P6: 0.82475611 | Q6: 0.012435369 | R6: 3.3773007 | S6: 0.10308021 | T6: 5.5449844 | U6: 0.5030714 | V6: 2.4935084 | W6: 0.25731303 | X6: 2.1817223 | Y6: 0.51640738 | Z6: 1.8873135 | AA6: 0.92341333 | AB6: 1.3524715 | AC6: 1.8456279 | AD6: 0.90816948 | AE6: 1.4700255
A7: LAM | B7: 2.8491017e-10 | C7: 1.9429269e-10 | D7: 1.0709434e-10 | E7: 7.2954923e-11 | F7: 1.0380525e-09 | G7: 6.2554652e-10 | H7: 2.6077531e-09 | I7: 1.110398e-09 | J7: 3.531826e-09 | K7: 9.1828836e-09 | L7: 0.00025342942 | M7: 0.028308686 | N7: 0.02128493 | O7: 0.26608662 | P7: 0.30085632 | Q7: 1.0294408 | R7: 2.852004 | S7: 3.2029193 | T7: 9.652379 | U7: 3.7245447 | V7: 4.1201262 | W7: 2.6113607 | X7: 2.7322957 | Y7: 3.4675468 | Z7: 2.9064893 | AA7: 12.39267 | AB7: 2.6690241 | AC7: 22.5576 | AD7: 1.774476 | AE7: 24.840889
A8: CPA | B8: 2.0573445e-10 | C8: 1.3925678e-10 | D8: 4.629892e-10 | E8: 3.0090165e-10 | F8: 5.9659092e-10 | G8: 4.1905051e-10 | H8: 1.2271507e-09 | I8: 6.315799e-10 | J8: 8.5435249e-06 | K8: 0.00040220832 | L8: 0.25239525 | M8: 0.014269256 | N8: 2.1703726 | O8: 0.15257039 | P8: 3.6555315 | Q8: 0.67163065 | R8: 8.3153789 | S8: 1.8167303 | T8: 13.054954 | U8: 5.7135857 | V8: 5.6691881 | W8: 2.7505647 | X8: 4.1069911 | Y8: 4.6883974 | Z8: 4.0151447 | AA8: 14.05314 | AB8: 3.8165357 | AC8: 15.961428 | AD8: 3.3064606 | AE8: 13.985167
A9: AFR | B9: 1.4817036e-10 | C9: 1.0080495e-10 | D9: 1.1344174e-10 | E9: 7.5596883e-11 | F9: 5.7576274e-10 | G9: 3.8333069e-10 | H9: 1.4620198e-09 | I9: 6.0014009e-10 | J9: 4.0396008e-09 | K9: 3.2684806e-09 | L9: 0.0053256339 | M9: 0.0014974765 | N9: 0.18232539 | O9: 0.054756654 | P9: 1.6021176 | Q9: 0.29029809 | R9: 14.106428 | S9: 2.2690961 | T9: 34.231651 | U9: 3.9370038 | V9: 13.592395 | W9: 2.648831 | X9: 10.541655 | Y9: 3.8956649 | Z9: 10.052946 | AA9: 24.32485 | AB9: 8.8025728 | AC9: 31.864989 | AD9: 8.3835887 | AE9: 37.088741
A10: SAS | B10: 9.2234391e-11 | C10: 6.4296686e-11 | D10: 8.0837602e-11 | E10: 5.6149618e-11 | F10: 3.26137e-10 | G10: 2.5280429e-10 | H10: 8.2048841e-10 | I10: 4.4789807e-10 | J10: 2.1210499e-08 | K10: 5.0236716e-09 | L10: 0.15828681 | M10: 0.0063167481 | N10: 1.4820756 | O10: 0.07577803 | P10: 2.0514472 | Q10: 0.71891315 | R10: 2.5972321 | S10: 1.1799789 | T10: 2.4704881 | U10: 1.4895644 | V10: 1.4253617 | W10: 0.52530535 | X10: 0.88945021 | Y10: 0.66727363 | Z10: 0.76026991 | AA10: 0.96067277 | AB10: 0.54823397 | AC10: 2.1297904 | AD10: 0.74750755 | AE10: 2.128504
A11: PAS | B11: 1.4623662e-10 | C11: 9.9582324e-11 | D11: 8.6516681e-11 | E11: 5.8395784e-11 | F11: 3.3103728e-10 | G11: 2.4364193e-10 | H11: 6.2743013e-10 | I11: 4.03652e-10 | J11: 1.9671359e-08 | K11: 1.1209797e-08 | L11: 0.48271311 | M11: 0.0087557048 | N11: 1.0662583 | O11: 0.099442111 | P11: 0.74978698 | Q11: 0.47687717 | R11: 0.36068232 | S11: 0.57205862 | T11: 0.32623814 | U11: 0.39139406 | V11: 0.37998459 | W11: 0.36422375 | X11: 0.25566805 | Y11: 0.87772442 | Z11: 0.16764668 | AA11: 0.55638418 | AB11: 0.13331421 | AC11: 0.43627574 | AD11: 0.36446175 | AE11: 1.2190147
A12: MEA | B12: 8.9640218e-11 | C12: 6.1341396e-11 | D12: 7.8984291e-11 | E12: 5.3095707e-11 | F12: 5.9066582e-10 | G12: 2.7745334e-10 | H12: 9.9119951e-06 | I12: 1.0056812e-09 | J12: 3.9690838e-06 | K12: 0.0005558565 | L12: 0.84134141 | M12: 0.036627968 | N12: 1.9177272 | O12: 0.32508073 | P12: 4.6944962 | Q12: 2.8575434 | R12: 6.1185212 | S12: 5.868482 | T12: 9.6400444 | U12: 8.6371632 | V12: 4.8996999 | W12: 6.2554572 | X12: 3.3751543 | Y12: 8.680124 | Z12: 2.8469887 | AA12: 12.756142 | AB12: 3.7866181 | AC12: 15.13061 | AD12: 3.4516004 | AE12: 13.118264

Sheet H2toMeOH
B1: 2010 | C1: 2010 | D1: 2020 | E1: 2020 | F1: 2030 | G1: 2030 | H1: 2040 | I1: 2040 | J1: 2050 | K1: 2050 | L1: 2060 | M1: 2060 | N1: 2070 | O1: 2070 | P1: 2080 | Q1: 2080 | R1: 2090 | S1: 2090 | T1: 2100 | U1: 2100 | V1: 2110 | W1: 2110 | X1: 2120 | Y1: 2120 | Z1: 2130 | AA1: 2130 | AB1: 2140 | AC1: 2140 | AD1: 2150 | AE1: 2150
B2: 1 | C2: 2 | D2: 1 | E2: 2 | F2: 1 | G2: 2 | H2: 1 | I2: 2 | J2: 1 | K2: 2 | L2: 1 | M2: 2 | N2: 1 | O2: 2 | P2: 1 | Q2: 2 | R2: 1 | S2: 2 | T2: 1 | U2: 2 | V2: 1 | W2: 2 | X2: 1 | Y2: 2 | Z2: 1 | AA2: 2 | AB2: 1 | AC2: 2 | AD2: 1 | AE2: 2
A3: EUR | B3: 0 | C3: 0 | D3: 0 | E3: 0 | F3: 1.9597598e-10 | G3: 1.0797874e-10 | H3: 3.288296e-10 | I3: 1.778361e-10 | J3: 9.069408e-09 | K3: 1.8846337e-10 | L3: 7.8561216e-10 | M3: 2.3330158e-10 | N3: 1.5462599e-09 | O3: 3.5104277e-10 | P3: 1.935901e-08 | Q3: 6.0707398e-10 | R3: 1.4532817e-05 | S3: 9.9818608e-10 | T3: 1.0036218e-05 | U3: 2.6433893e-09 | V3: 2.115958e-08 | W3: 7.434841e-09 | X3: 3.4368069e-08 | Y3: 1.4466932e-08 | Z3: 3.4311375e-08 | AA3: 6.4146167e-07 | AB3: 5.6190605e-08 | AC3: 2.1060499e-07 | AD3: 9.5208806e-08 | AE3: 6.081393e-07
A4: NAM | B4: 0 | C4: 0 | D4: 0 | E4: 0 | F4: 2.9061839e-10 | G4: 1.3225538e-10 | H4: 4.2080332e-10 | I4: 1.8573039e-10 | J4: 1.1369868 | K4: 1.7244584e-10 | L4: 1.9981844e-09 | M4: 1.9725848e-10 | N4: 2.0200144e-09 | O4: 3.9885096e-10 | P4: 4.9476023e-09 | Q4: 6.687278e-10 | R4: 0.28082562 | S4: 1.1468518e-09 | T4: 0.6676125 | U4: 5.4364485e-09 | V4: 1.5587317e-08 | W4: 6.5697741e-09 | X4: 1.7417409e-08 | Y4: 0.08806521 | Z4: 2.719174e-08 | AA4: 0.92136903 | AB4: 5.9902855e-08 | AC4: 0.61255934 | AD4: 1.0628755e-07 | AE4: 0.40725444
A5: PAO | B5: 0 | C5: 0 | D5: 0 | E5: 0 | F5: 1.9091323e-10 | G5: 1.0572441e-10 | H5: 3.4209285e-10 | I5: 1.824557e-10 | J5: 4.9668298e-09 | K5: 1.9372319e-10 | L5: 7.2009189e-10 | M5: 2.3110606e-10 | N5: 1.4692743e-09 | O5: 3.9447292e-10 | P5: 6.2010544e-09 | Q5: 6.2741086e-10 | R5: 0.0973657 | S5: 1.1386884e-09 | T5: 1.0083979 | U5: 3.5588129e-09 | V5: 2.2669098e-08 | W5: 5.4064361e-09 | X5: 1.6199896e-07 | Y5: 0.15733905 | Z5: 2.9148784e-07 | AA5: 1.5695991 | AB5: 3.6498093e-06 | AC5: 1.3729312 | AD5: 1.536667e-07 | AE5: 1.6475167
A6: FSU | B6: 0 | C6: 0 | D6: 0 | E6: 0 | F6: 3.3363252e-10 | G6: 2.0564223e-10 | H6: 6.0911628e-10 | I6: 2.7832044e-10 | J6: 0.099520814 | K6: 2.474315e-10 | L6: 1.2034259e-09 | M6: 2.3148092e-10 | N6: 1.5867749e-09 | O6: 3.9964871e-10 | P6: 4.8411781e-09 | Q6: 5.600854e-10 | R6: 0.060764905 | S6: 9.7236837e-10 | T6: 0.48527866 | U6: 4.4630624e-09 | V6: 1.0476085e-08 | W6: 4.6827045e-09 | X6: 1.846607e-08 | Y6: 5.5033999e-08 | Z6: 2.7999922e-08 | AA6: 0.060228506 | AB6: 4.5661162e-08 | AC6: 0.072273499 | AD6: 8.1849503e-08 | AE6: 0.048049596
A7: LAM | B7: 0 | C7: 0 | D7: 0 | E7: 0 | F7: 6.704004e-10 | G7: 2.6719665e-10 | H7: 5.8629389e-10 | I7: 1.5790274e-10 | J7: 1.0334142 | K7: 1.6521442e-10 | L7: 2.948036e-09 | M7: 2.1090035e-10 | N7: 2.3555833e-09 | O7: 3.290471e-10 | P7: 0.16045681 | Q7: 6.9451713e-10 | R7: 0.76015664 | S7: 1.5175354e-09 | T7: 3.312931 | U7: 5.6787863e-09 | V7: 0.22315066 | W7: 1.6736431e-08 | X7: 7.3163137e-08 | Y7: 0.29611315 | Z7: 8.3700895e-08 | AA7: 2.8681827 | AB7: 7.8139949e-08 | AC7: 1.9068636 | AD7: 1.0231413e-07 | AE7: 1.2677479
A8: CPA | B8: 0 | C8: 0 | D8: 0 | E8: 0 | F8: 3.9074619e-10 | G8: 7.4552451e-11 | H8: 2.5573213e-10 | I8: 1.4172735e-10 | J8: 1.3794912e-09 | K8: 1.6360427e-10 | L8: 7.3619045e-10 | M8: 1.920008e-10 | N8: 1.5009154e-09 | O8: 3.2103919e-10 | P8: 1.0008344e-05 | Q8: 5.9009672e-10 | R8: 0.28082528 | S8: 1.1654769e-09 | T8: 0.18685428 | U8: 4.2011112e-09 | V8: 2.350806e-08 | W8: 1.0999326e-08 | X8: 5.1617182e-08 | Y8: 0.46332532 | Z8: 9.9029754e-06 | AA8: 4.4328729 | AB8: 9.8478614e-06 | AC8: 3.561467 | AD8: 9.2386914e-06 | AE8: 2.3677851
A9: AFR | B9: 0 | C9: 0 | D9: 0 | E9: 0 | F9: 4.0151148e-10 | G9: 1.6282367e-10 | H9: 6.0066341e-10 | I9: 2.8631941e-10 | J9: 0.11763249 | K9: 2.0583259e-10 | L9: 1.131667e-09 | M9: 2.462007e-10 | N9: 1.9759945e-09 | O9: 3.2221158e-10 | P9: 1.1129142e-08 | Q9: 7.1079175e-10 | R9: 2.0910149 | S9: 1.4813728e-09 | T9: 10.846199 | U9: 8.381239e-09 | V9: 2.2751365e-07 | W9: 8.5422858e-09 | X9: 2.6799396e-07 | Y9: 1.0218862 | Z9: 7.5943626e-08 | AA9: 9.6446919 | AB9: 1.2787944e-07 | AC9: 6.4121092 | AD9: 1.9942541e-07 | AE9: 4.2629837
A10: SAS | B10: 0 | C10: 0 | D10: 0 | E10: 0 | F10: 3.4542961e-10 | G10: 1.8879993e-10 | H10: 2.2709654e-10 | I10: 1.2788482e-10 | J10: 1.9360071e-09 | K10: 1.8334933e-10 | L10: 7.4261897e-10 | M10: 2.609123e-10 | N10: 2.1080201e-09 | O10: 4.9363985e-10 | P10: 9.9760087e-06 | Q10: 7.7083445e-10 | R10: 1.0010885e-05 | S10: 1.3211388e-09 | T10: 1.0002072e-05 | U10: 4.3652485e-09 | V10: 9.8677405e-06 | W10: 9.2180371e-09 | X10: 9.8879012e-06 | Y10: 5.2041245e-08 | Z10: 9.5983127e-06 | AA10: 1.7037255e-07 | AB10: 9.2554857e-06 | AC10: 8.3418841e-08 | AD10: 6.6507956e-06 | AE10: 8.7183315e-06
A11: PAS | B11: 0 | C11: 0 | D11: 0 | E11: 0 | F11: 4.5344615e-10 | G11: 1.0300796e-10 | H11: 3.0826031e-10 | I11: 1.6329941e-10 | J11: 5.4329865e-09 | K11: 1.685767e-10 | L11: 7.6697952e-10 | M11: 2.2646293e-10 | N11: 1.7272353e-09 | O11: 3.8616776e-10 | P11: 5.1646908e-09 | Q11: 5.9048277e-10 | R11: 4.3607331e-09 | S11: 7.0780027e-10 | T11: 6.0029841e-08 | U11: 1.3775043e-09 | V11: 1.9192706e-08 | W11: 3.646365e-09 | X11: 6.9439632e-08 | Y11: 4.6767943e-09 | Z11: 5.0449925e-08 | AA11: 5.2841764e-09 | AB11: 2.1057507e-07 | AC11: 1.0077623e-08 | AD11: 1.0306252e-07 | AE11: 1.6858519e-08
A12: MEA | B12: 0 | C12: 0 | D12: 0 | E12: 0 | F12: 3.1008482e-10 | G12: 7.7577197e-11 | H12: 6.8781672e-10 | I12: 2.0799588e-10 | J12: 3.4729629e-09 | K12: 2.528807e-10 | L12: 1.0877938e-09 | M12: 2.3923538e-10 | N12: 5.8424337e-09 | O12: 5.1265308e-10 | P12: 0.040367515 | Q12: 1.0239567e-09 | R12: 0.46289882 | S12: 1.6730245e-09 | T12: 2.7279671 | U12: 9.2398982e-09 | V12: 1.8279592e-07 | W12: 4.370258e-08 | X12: 1.5086895e-07 | Y12: 3.4243031 | Z12: 6.4728273e-08 | AA12: 4.895424 | AB12: 1.1726418e-07 | AC12: 3.2546399 | AD12: 1.0291769e-07 | AE12: 2.1637937

Sheet MeOHtotrsp
B1: 2010 | C1: 2010 | D1: 2020 | E1: 2020 | F1: 2030 | G1: 2030 | H1: 2040 | I1: 2040 | J1: 2050 | K1: 2050 | L1: 2060 | M1: 2060 | N1: 2070 | O1: 2070 | P1: 2080 | Q1: 2080 | R1: 2090 | S1: 2090 | T1: 2100 | U1: 2100 | V1: 2110 | W1: 2110 | X1: 2120 | Y1: 2120 | Z1: 2130 | AA1: 2130 | AB1: 2140 | AC1: 2140 | AD1: 2150 | AE1: 2150
B2: 1 | C2: 2 | D2: 1 | E2: 2 | F2: 1 | G2: 2 | H2: 1 | I2: 2 | J2: 1 | K2: 2 | L2: 1 | M2: 2 | N2: 1 | O2: 2 | P2: 1 | Q2: 2 | R2: 1 | S2: 2 | T2: 1 | U2: 2 | V2: 1 | W2: 2 | X2: 1 | Y2: 2 | Z2: 1 | AA2: 2 | AB2: 1 | AC2: 2 | AD2: 1 | AE2: 2
A3: EUR | B3: 2.1193477e-10 | C3: 1.465169e-10 | D3: 0.27857358 | E3: 0.27857358 | F3: 0.94374813 | G3: 0.94374813 | H3: 0.77111093 | I3: 2.6690396 | J3: 0.39224221 | K3: 2.1807997 | L3: 0.20492093 | M3: 5.5856334 | N3: 0.11065482 | O3: 7.7454857 | P3: 0.063874349 | Q3: 8.6543196 | R3: 0.28081518 | S3: 7.9432814 | T3: 0.22944664 | U3: 6.6188937 | V3: 0.16180857 | W3: 8.2869109 | X3: 0.11444881 | Y3: 9.6758754 | Z3: 0.081123048 | AA3: 9.8540403 | AB3: 0.057588782 | AC3: 9.3935136 | AD3: 0.040927079 | AE3: 9.2823005
A4: NAM | B4: 1.7972093e-10 | C4: 1.2268416e-10 | D4: 0.27857358 | E4: 0.27857358 | F4: 0.94374813 | G4: 0.94374813 | H4: 0.77111093 | I4: 2.6690396 | J4: 0.39758777 | K4: 6.6575411 | L4: 0.21115573 | M4: 7.9890513 | N4: 0.10919787 | O4: 9.5868637 | P4: 0.064601683 | Q4: 9.0570077 | R4: 0.28081563 | S4: 8.4472802 | T4: 0.23549514 | U4: 7.0193567 | V4: 0.14992424 | W4: 8.7057351 | X4: 0.097806676 | Y4: 9.192669 | Z4: 0.065165462 | AA4: 9.7035477 | AB4: 0.044162228 | AC4: 9.1403981 | AD4: 0.03032899 | AE4: 8.6622828
A5: PAO | B5: 4.517772e-10 | C5: 3.089956e-10 | D5: 0.27857358 | E5: 0.27857358 | F5: 0.94374813 | G5: 0.94374813 | H5: 0.77111093 | I5: 2.2067687 | J5: 0.34539432 | K5: 1.8030907 | L5: 0.15417423 | M5: 1.5282807 | N5: 0.068906482 | O5: 2.6565365 | P5: 0.12516075 | Q5: 2.3379902 | R5: 0.097355808 | S5: 2.0036059 | T5: 0.081049853 | U5: 1.3360656 | V5: 0.056393827 | W5: 2.36256 | X5: 0.039501156 | Y5: 2.6595252 | Z5: 0.027803922 | AA5: 3.4747885 | AB5: 0.019640003 | AC5: 3.224093 | AD5: 0.013909535 | AE5: 3.4474753
A6: FSU | B6: 1.943289e-10 | C6: 1.3307673e-10 | D6: 0.27857358 | E6: 0.27857358 | F6: 0.94374813 | G6: 0.94374813 | H6: 2.4990758 | I6: 2.5184525 | J6: 1.4474202 | K6: 2.3368601 | L6: 0.86838547 | M6: 2.5555591 | N6: 0.54636784 | O6: 3.160271 | P6: 0.36382852 | Q6: 2.7346686 | R6: 0.29538132 | S6: 2.4520175 | T6: 0.27503319 | U6: 1.7453318 | V6: 0.195929 | W6: 2.6162132 | X6: 0.1381646 | Y6: 3.2539666 | Z6: 0.09772201 | AA6: 3.8634636 | AB6: 0.069265737 | AC6: 3.7777207 | AD6: 0.049171863 | AE6: 3.6983647
A7: LAM | B7: 1.6258133e-10 | C7: 1.1070638e-10 | D7: 0.27857358 | E7: 0.27857358 | F7: 0.94374813 | G7: 0.94374813 | H7: 2.6690396 | I7: 2.6690396 | J7: 1.6126904 | K7: 2.4994409 | L7: 0.82912285 | M7: 2.7813194 | N7: 0.4422906 | O7: 3.9485025 | P7: 0.25860679 | Q7: 4.2406245 | R7: 0.76014621 | S7: 4.6603265 | T7: 0.54495608 | U7: 4.8127891 | V7: 0.38109983 | W7: 5.5691685 | X7: 0.26781453 | Y7: 5.6731911 | Z7: 0.18895039 | AA7: 5.8201746 | AB7: 0.13368932 | AC7: 5.5278237 | AD7: 0.094783247 | AE7: 5.3026337
A8: CPA | B8: 2.0778678e-10 | C8: 1.418911e-10 | D8: 0.27857358 | E8: 0.27857358 | F8: 0.94374813 | G8: 0.94374813 | H8: 0.77111094 | I8: 2.6690396 | J8: 0.34956385 | K8: 2.1807997 | L8: 0.15663475 | M8: 1.7818721 | N8: 0.069187771 | O8: 1.4559193 | P8: 0.033681314 | Q8: 2.5440769 | R8: 0.28081528 | S8: 3.5181371 | T8: 0.13671307 | U8: 4.143398 | V8: 0.068592485 | W8: 4.9062705 | X8: 0.034418206 | Y8: 5.3336707 | Z8: 0.017273154 | AA8: 6.0745987 | AB8: 0.0086713713 | AC8: 5.9225062 | AD8: 0.004356281 | AE8: 5.8883424
A9: AFR | B9: 2.6846555e-10 | C9: 1.8328116e-10 | D9: 0.092181069 | E9: 0.092181069 | F9: 0.94374813 | G9: 0.94374813 | H9: 2.6690396 | I9: 2.6690396 | J9: 1.1866505 | K9: 1.2964403 | L9: 0.51017198 | M9: 1.1873408 | N9: 0.21513824 | O9: 1.7946049 | P9: 0.63054598 | Q9: 2.2977191 | R9: 0.91382225 | S9: 3.2522632 | T9: 0.61018721 | U9: 4.4532147 | V9: 0.41795145 | W9: 4.7293007 | X9: 0.28935687 | Y9: 4.7844341 | Z9: 0.20193451 | AA9: 4.8572023 | AB9: 0.14175427 | AC9: 4.7786025 | AD9: 0.099934544 | AE9: 4.7076116
A10: SAS | B10: 0.02212 | C10: 0.02212 | D10: 0.27857358 | E10: 0.27857358 | F10: 0.94374813 | G10: 0.94374813 | H10: 2.6690396 | I10: 2.6690396 | J10: 1.1605288 | K10: 2.1807997 | L10: 0.49270794 | M10: 1.7818721 | N10: 0.20228966 | O10: 1.7882374 | P10: 0.09846852 | Q10: 4.6053967 | R10: 0.97198316 | S10: 8.2052456 | T10: 0.79418127 | U10: 11.954517 | V10: 0.54957953 | W10: 12.72495 | X10: 0.38340785 | Y10: 13.131359 | Z10: 0.26907857 | AA10: 13.452657 | AB10: 0.18966078 | AC10: 13.627911 | AD10: 0.13410122 | AE10: 13.65208
A11: PAS | B11: 2.3146133e-10 | C11: 1.5829327e-10 | D11: 0.27857358 | E11: 0.27857358 | F11: 0.94374813 | G11: 0.94374813 | H11: 0.93672505 | I11: 2.6690396 | J11: 0.3818547 | K11: 2.1807997 | L11: 0.097925155 | M11: 1.7818721 | N11: 0.043175746 | O11: 1.4559193 | P11: 0.021017696 | Q11: 3.0485799 | R11: 0.1958733 | S11: 4.683942 | T11: 0.27872557 | U11: 5.7270149 | V11: 0.19980151 | W11: 6.7560181 | X11: 0.11707832 | Y11: 7.4699414 | Z11: 0.078357283 | AA11: 8.5853093 | AB11: 0.053291185 | AC11: 9.018077 | AD11: 0.036697989 | AE11: 8.8981554
A12: MEA | B12: 0.02212 | C12: 0.02212 | D12: 0.11424879 | E12: 0.11424879 | F12: 0.94374813 | G12: 0.94374813 | H12: 0.77111094 | I12: 2.6690392 | J12: 0.35501151 | K12: 2.0045329 | L12: 0.16385684 | M12: 1.6581784 | N12: 0.07631423 | O12: 1.455919 | P12: 0.040361024 | Q12: 1.189592 | R12: 0.19141127 | S12: 2.009703 | T12: 0.12202007 | U12: 2.487159 | V12: 0.083771946 | W12: 3.1400157 | X12: 0.058098374 | Y12: 3.3141952 | Z12: 0.040598002 | AA12: 3.4244961 | AB12: 0.028526645 | AC12: 3.3341424 | AD12: 0.020126405 | AE12: 3.2791448

Sheet Efuels
C1: 1 | D1: 2
B2: EUR | C2: 0.11065482 | D2: 7.7454857
B3: NAM | C3: 0.10919787 | D3: 9.5868637
B4: PAO | C4: 0.068906482 | D4: 2.6565365
B5: FSU | C5: 0.54636784 | D5: 3.160271
B6: LAM | C6: 0.4422906 | D6: 3.9485025
B7: CPA | C7: 0.069187771 | D7: 1.4559193
B8: AFR | C8: 0.21513824 | D8: 1.7946049
B9: SAS | C9: 0.20228966 | D9: 1.7882374
B10: PAS | C10: 0.043175746 | D10: 1.4559193
B11: MEA | C11: 0.07631423 | D11: 1.455919
C13: 1 | D13: 2
B14: EUR | C14: 1.5462599e-09 | D14: 3.5104277e-10
B15: NAM | C15: 2.0200144e-09 | D15: 3.9885096e-10
B16: PAO | C16: 1.4692743e-09 | D16: 3.9447292e-10
B17: FSU | C17: 1.5867749e-09 | D17: 3.9964871e-10
B18: LAM | C18: 2.3555833e-09 | D18: 3.290471e-10
B19: CPA | C19: 1.5009154e-09 | D19: 3.2103919e-10
B20: AFR | C20: 1.9759945e-09 | D20: 3.2221158e-10
B21: SAS | C21: 2.1080201e-09 | D21: 4.9363985e-10
B22: PAS | C22: 1.7272353e-09 | D22: 3.8616776e-10
B23: MEA | C23: 5.8424337e-09 | D23: 5.1265308e-10
C25: 1 | D25: 2
B26: EUR | C26: 0.62941781 | D26: 0.006893299
B27: NAM | C27: 0.79790904 | D27: 0.58253448
B28: PAO | C28: 2.3275076 | D28: 0.13085024
B29: FSU | C29: 0.097420151 | D29: 1.9466502e-08
B30: LAM | C30: 0.02128493 | D30: 0.26608662
B31: CPA | C31: 2.1703726 | D31: 0.15257039
B32: AFR | C32: 0.18232539 | D32: 0.054756654
B33: SAS | C33: 1.4820756 | D33: 0.07577803
B34: PAS | C34: 1.0662583 | D34: 0.099442111
B35: MEA | C35: 1.9177272 | D35: 0.32508073

Sheet electrolyser
A1: 1 | B1: 2
A2: 358.20371 | B2: 330.45511

Sheet fuelsynthesis
A1: 1 | B1: 2
A2: 351.61785 | B2: 480.79529

Sheet VRE
A1: 1 | B1: 2
A2: 0.51606341 | B2: 0.99598044

Sheet bio
A1: 1 | B1: 2
A2: 15.628099 | B2: 28.921182

Sheet Infra_lim
A1: 1 | B1: 2
A2: 0.31308468 | B2: 0.86328935

Sheet fc_lim
A1: 1 | B1: 2
A2: 0.54943263 | B2: -0.86027298

Sheet cost_strg
A1: 1 | B1: 2
A2: 0.012102295 | B2: 0.011024672

Sheet CO2aircapt_cost
A1: 1 | B1: 2
A2: 0.8297738 | B2: 0.24667199

Sheet eff_el2h2
A1: 1 | B1: 2
A2: 0.67121778 | B2: 0.63507472

Sheet eff_h22meoh
A1: 1 | B1: 2
A2: 0.87164864 | B2: 0.75731618

Sheet carbon_price
B1: 2010 | C1: 2010 | D1: 2020 | E1: 2020 | F1: 2030 | G1: 2030 | H1: 2040 | I1: 2040 | J1: 2050 | K1: 2050 | L1: 2060 | M1: 2060 | N1: 2070 | O1: 2070 | P1: 2080 | Q1: 2080 | R1: 2090 | S1: 2090 | T1: 2100 | U1: 2100 | V1: 2110 | W1: 2110 | X1: 2120 | Y1: 2120 | Z1: 2130 | AA1: 2130 | AB1: 2140 | AC1: 2140 | AD1: 2150 | AE1: 2150
B2: 1 | C2: 2 | D2: 1 | E2: 2 | F2: 1 | G2: 2 | H2: 1 | I2: 2 | J2: 1 | K2: 2 | L2: 1 | M2: 2 | N2: 1 | O2: 2 | P2: 1 | Q2: 2 | R2: 1 | S2: 2 | T2: 1 | U2: 2 | V2: 1 | W2: 2 | X2: 1 | Y2: 2 | Z2: 1 | AA2: 2 | AB2: 1 | AC2: 2 | AD2: 1 | AE2: 2
A3: EUR | B3: 0.016712154 | C3: 0.014858636 | D3: 0.10275209 | E3: 0.10802056 | F3: 0.019667643 | G3: 0.013017637 | H3: 0.032036519 | I3: 0.021204358 | J3: 0.052184113 | K3: 0.034539665 | L3: 0.085002422 | M3: 0.056261475 | N3: 0.13845999 | O3: 0.091644014 | P3: 0.22553673 | Q3: 0.14927844 | R3: 0.36737557 | S3: 0.24315885 | T3: 0.59841609 | U3: 0.39608015 | V3: 0.068582005 | W3: 0.13477573 | X3: 0.088064396 | Y3: 0.20190314 | Z3: 0.11322355 | AA3: 0.26230023 | AB3: 0.13417156 | AC3: 0.48632383 | AD3: 0.18003925 | AE3: 0.80301317
A4: NAM | B4: 2.3155185e-12 | C4: 6.4364681e-12 | D4: 0.036267058 | E4: 0.033774794 | F4: 0.019667643 | G4: 0.013017637 | H4: 0.032036519 | I4: 0.021204358 | J4: 0.052184113 | K4: 0.034539665 | L4: 0.085002422 | M4: 0.056261475 | N4: 0.13845999 | O4: 0.091644014 | P4: 0.22553673 | Q4: 0.14927844 | R4: 0.36737557 | S4: 0.24315885 | T4: 0.59841609 | U4: 0.39608015 | V4: 0.068582005 | W4: 0.13477573 | X4: 0.088064396 | Y4: 0.20190314 | Z4: 0.11322355 | AA4: 0.26230023 | AB4: 0.13417156 | AC4: 0.48632383 | AD4: 0.18003925 | AE4: 0.80301317
A5: PAO | B5: 1.2554113e-12 | C5: 3.6195183e-12 | D5: 0.19589844 | E5: 0.19696116 | F5: 0.019667643 | G5: 0.013017637 | H5: 0.032036519 | I5: 0.021204358 | J5: 0.052184113 | K5: 0.034539665 | L5: 0.085002422 | M5: 0.056261475 | N5: 0.13845999 | O5: 0.091644014 | P5: 0.22553673 | Q5: 0.14927844 | R5: 0.36737557 | S5: 0.24315885 | T5: 0.59841609 | U5: 0.39608015 | V5: 0.068582005 | W5: 0.13477573 | X5: 0.088064396 | Y5: 0.20190314 | Z5: 0.11322355 | AA5: 0.26230023 | AB5: 0.13417156 | AC5: 0.48632383 | AD5: 0.18003925 | AE5: 0.80301317
A6: FSU | B6: 0.017087642 | C6: 0.017093517 | D6: 0.05612563 | E6: 0.058100642 | F6: 0.019667643 | G6: 0.013017637 | H6: 0.032036519 | I6: 0.021204358 | J6: 0.052184113 | K6: 0.034539665 | L6: 0.085002422 | M6: 0.056261475 | N6: 0.13845999 | O6: 0.091644014 | P6: 0.22553673 | Q6: 0.14927844 | R6: 0.36737557 | S6: 0.24315885 | T6: 0.59841609 | U6: 0.39608015 | V6: 0.068582005 | W6: 0.13477573 | X6: 0.088064396 | Y6: 0.20190314 | Z6: 0.11322355 | AA6: 0.26230023 | AB6: 0.13417156 | AC6: 0.48632383 | AD6: 0.18003925 | AE6: 0.80301317
A7: LAM | B7: 1.3120685e-12 | C7: 3.3820505e-12 | D7: 0.19272447 | E7: 0.18686456 | F7: 0.019667643 | G7: 0.013017637 | H7: 0.032036519 | I7: 0.021204358 | J7: 0.052184113 | K7: 0.034539665 | L7: 0.085002422 | M7: 0.056261475 | N7: 0.13845999 | O7: 0.091644014 | P7: 0.22553673 | Q7: 0.14927844 | R7: 0.36737557 | S7: 0.24315885 | T7: 0.59841609 | U7: 0.39608015 | V7: 0.068582005 | W7: 0.13477573 | X7: 0.088064396 | Y7: 0.20190314 | Z7: 0.11322355 | AA7: 0.26230023 | AB7: 0.13417156 | AC7: 0.48632383 | AD7: 0.18003925 | AE7: 0.80301317
A8: CPA | B8: 7.3818095e-14 | C8: 1.6750854e-13 | D8: 1.1891412e-13 | E8: 3.5521927e-13 | F8: 0.019667643 | G8: 0.013017637 | H8: 0.032036519 | I8: 0.021204358 | J8: 0.052184113 | K8: 0.034539665 | L8: 0.085002422 | M8: 0.056261475 | N8: 0.13845999 | O8: 0.091644014 | P8: 0.22553673 | Q8: 0.14927844 | R8: 0.36737557 | S8: 0.24315885 | T8: 0.59841609 | U8: 0.39608015 | V8: 0.068582005 | W8: 0.13477573 | X8: 0.088064396 | Y8: 0.20190314 | Z8: 0.11322355 | AA8: 0.26230023 | AB8: 0.13417156 | AC8: 0.48632383 | AD8: 0.18003925 | AE8: 0.80301317
A9: AFR | B9: 6.9342481e-12 | C9: 1.3004986e-11 | D9: 0.072417447 | E9: 0.074379215 | F9: 0.019667643 | G9: 0.013017637 | H9: 0.032036519 | I9: 0.021204358 | J9: 0.052184113 | K9: 0.034539665 | L9: 0.085002422 | M9: 0.056261475 | N9: 0.13845999 | O9: 0.091644014 | P9: 0.22553673 | Q9: 0.14927844 | R9: 0.36737557 | S9: 0.24315885 | T9: 0.59841609 | U9: 0.39608015 | V9: 0.068582005 | W9: 0.13477573 | X9: 0.088064396 | Y9: 0.20190314 | Z9: 0.11322355 | AA9: 0.26230023 | AB9: 0.13417156 | AC9: 0.48632383 | AD9: 0.18003925 | AE9: 0.80301317
A10: SAS | B10: 1.7222718e-13 | C10: 4.0983403e-13 | D10: 0.15524521 | E10: 0.14632189 | F10: 0.019667643 | G10: 0.013017637 | H10: 0.032036519 | I10: 0.021204358 | J10: 0.052184113 | K10: 0.034539665 | L10: 0.085002422 | M10: 0.056261475 | N10: 0.13845999 | O10: 0.091644014 | P10: 0.22553673 | Q10: 0.14927844 | R10: 0.36737557 | S10: 0.24315885 | T10: 0.59841609 | U10: 0.39608015 | V10: 0.068582005 | W10: 0.13477573 | X10: 0.088064396 | Y10: 0.20190314 | Z10: 0.11322355 | AA10: 0.26230023 | AB10: 0.13417156 | AC10: 0.48632383 | AD10: 0.18003925 | AE10: 0.80301317
A11: PAS | B11: 4.5884565e-13 | C11: 1.1498277e-12 | D11: 0.12454847 | E11: 0.12329883 | F11: 0.019667643 | G11: 0.013017637 | H11: 0.032036519 | I11: 0.021204358 | J11: 0.052184113 | K11: 0.034539665 | L11: 0.085002422 | M11: 0.056261475 | N11: 0.13845999 | O11: 0.091644014 | P11: 0.22553673 | Q11: 0.14927844 | R11: 0.36737557 | S11: 0.24315885 | T11: 0.59841609 | U11: 0.39608015 | V11: 0.068582005 | W11: 0.13477573 | X11: 0.088064396 | Y11: 0.20190314 | Z11: 0.11322355 | AA11: 0.26230023 | AB11: 0.13417156 | AC11: 0.48632383 | AD11: 0.18003925 | AE11: 0.80301317
A12: MEA | B12: 1.4757544e-13 | C12: 3.5855984e-13 | D12: 0.15447164 | E12: 0.14868138 | F12: 0.019667643 | G12: 0.013017637 | H12: 0.032036519 | I12: 0.021204358 | J12: 0.052184113 | K12: 0.034539665 | L12: 0.085002422 | M12: 0.056261475 | N12: 0.13845999 | O12: 0.091644014 | P12: 0.22553673 | Q12: 0.14927844 | R12: 0.36737557 | S12: 0.24315885 | T12: 0.59841609 | U12: 0.39608015 | V12: 0.068582005 | W12: 0.13477573 | X12: 0.088064396 | Y12: 0.20190314 | Z12: 0.11322355 | AA12: 0.26230023 | AB12: 0.13417156 | AC12: 0.48632383 | AD12: 0.18003925 | AE12: 0.80301317

Sheet mc_lf_el2h2
B1: 2010 | C1: 2010 | D1: 2020 | E1: 2020 | F1: 2030 | G1: 2030 | H1: 2040 | I1: 2040 | J1: 2050 | K1: 2050 | L1: 2060 | M1: 2060 | N1: 2070 | O1: 2070 | P1: 2080 | Q1: 2080 | R1: 2090 | S1: 2090 | T1: 2100 | U1: 2100 | V1: 2110 | W1: 2110 | X1: 2120 | Y1: 2120 | Z1: 2130 | AA1: 2130 | AB1: 2140 | AC1: 2140 | AD1: 2150 | AE1: 2150
B2: 1 | C2: 2 | D2: 1 | E2: 2 | F2: 1 | G2: 2 | H2: 1 | I2: 2 | J2: 1 | K2: 2 | L2: 1 | M2: 2 | N2: 1 | O2: 2 | P2: 1 | Q2: 2 | R2: 1 | S2: 2 | T2: 1 | U2: 2 | V2: 1 | W2: 2 | X2: 1 | Y2: 2 | Z2: 1 | AA2: 2 | AB2: 1 | AC2: 2 | AD2: 1 | AE2: 2
A3: EUR | B3: 0.072962622 | C3: 0.072949488 | D3: 0.056951627 | E3: 0.054907071 | F3: 0.066029656 | G3: 0.06293601 | H3: 0.067256909 | I3: 0.047102376 | J3: 8.3424929e-07 | K3: 0.11300409 | L3: 0.49315054 | M3: 0.19399111 | N3: 0.40151661 | O3: 0.18493155 | P3: 0.4034513 | Q3: 0.2465753 | R3: 0.36613497 | S3: 0.22402553 | T3: 0.35815245 | U3: 0.23097778 | V3: 0.22222001 | W3: 0.18546736 | X3: 0.35238317 | Y3: 0.22586692 | Z3: 0.37194755 | AA3: 0.24446542 | AB3: 0.40239174 | AC3: 0.23516273 | AD3: 0.38082153 | AE3: 0.23590886
A4: NAM | B4: 1.8555725e-08 | C4: 1.5419967e-08 | D4: 0.22163112 | E4: 0.22816777 | F4: 6.4954593e-09 | G4: 5.0572838e-09 | H4: 0.090372725 | I4: 9.2925831e-09 | J4: 6.4486239e-08 | K4: 1.8280785e-07 | L4: 0.38732871 | M4: 0.43493145 | N4: 0.39369153 | O4: 0.37342699 | P4: 0.37490106 | Q4: 0.34318617 | R4: 0.34970763 | S4: 0.26652119 | T4: 0.35547002 | U4: 0.31986371 | V4: 0.32716003 | W4: 0.30643671 | X4: 0.32931649 | Y4: 0.31458336 | Z4: 0.35074977 | AA4: 0.2965142 | AB4: 0.35837715 | AC4: 0.29848304 | AD4: 0.3433035 | AE4: 0.29873129
A5: PAO | B5: 0.05296344 | C5: 0.053063471 | D5: 0.021404294 | E5: 0.02175764 | F5: 0.069653821 | G5: 0.046561431 | H5: 0.15033779 | I5: 0.062611924 | J5: 8.8133222e-08 | K5: 0.1513099 | L5: 0.69280819 | M5: 0.24829166 | N5: 0.56479362 | O5: 0.26979778 | P5: 0.51571974 | Q5: 0.22549767 | R5: 0.45418648 | S5: 0.25968394 | T5: 0.43528366 | U5: 0.2649884 | V5: 0.39402496 | W5: 0.24338273 | X5: 0.44519271 | Y5: 0.24250921 | Z5: 0.51942364 | AA5: 0.28855079 | AB5: 0.50654932 | AC5: 0.28974658 | AD5: 0.48261652 | AE5: 0.28823489
A6: FSU | B6: 0.073927966 | C6: 0.073719358 | D6: 0.044748123 | E6: 0.044614902 | F6: 0.076534473 | G6: 0.06919143 | H6: 0.090911894 | I6: 0.080778044 | J6: 0.091201862 | K6: 0.087974846 | L6: 0.11644412 | M6: 0.14267735 | N6: 0.88972504 | O6: 0.21302815 | P6: 0.73187306 | Q6: 0.55454097 | R6: 0.53693086 | S6: 0.35922273 | T6: 0.46045547 | U6: 0.18046815 | V6: 0.31144818 | W6: 0.12781689 | X6: 0.40988508 | Y6: 0.17866437 | Z6: 0.53332788 | AA6: 0.18885574 | AB6: 0.57486503 | AC6: 0.20302137 | AD6: 0.58062023 | AE6: 0.24322588
A7: LAM | B7: 0.097348189 | C7: 0.097721264 | D7: 0.020034384 | E7: 0.019933412 | F7: 0.095528161 | G7: 0.085041778 | H7: 0.12217073 | I7: 0.096699584 | J7: 0.096668646 | K7: 4.3325777e-06 | L7: 0.21814261 | M7: 0.33561625 | N7: 0.28458894 | O7: 0.29840053 | P7: 0.3749998 | Q7: 0.29914997 | R7: 0.37499999 | S7: 0.31996963 | T7: 0.37225499 | U7: 0.2872822 | V7: 0.23900355 | W7: 0.28187253 | X7: 0.23809949 | Y7: 0.28355417 | Z7: 0.37129949 | AA7: 0.28643874 | AB7: 0.37499994 | AC7: 0.29174766 | AD7: 0.375 | AE7: 0.29236618
A8: CPA | B8: 0.0717105 | C8: 0.071533816 | D8: 0.0798307 | E8: 0.076052374 | F8: 0.05703026 | G8: 0.057876555 | H8: 0.072522218 | I8: 0.053931824 | J8: 0.00015773081 | K8: 0.2965429 | L8: 0.41810576 | M8: 0.18595888 | N8: 0.37737642 | O8: 0.18595891 | P8: 0.37528342 | Q8: 0.18595893 | R8: 0.36898686 | S8: 0.25274125 | T8: 0.37385929 | U8: 0.27190737 | V8: 0.24419759 | W8: 0.18682225 | X8: 0.26569295 | Y8: 0.27804094 | Z8: 0.38037014 | AA8: 0.29341774 | AB8: 0.39424108 | AC8: 0.29175613 | AD8: 0.37257681 | AE8: 0.28579885
A9: AFR | B9: 0.05348115 | C9: 0.053579092 | D9: 0.021286287 | E9: 0.020712062 | F9: 0.055595534 | G9: 0.053491808 | H9: 0.072547447 | I9: 0.043579424 | J9: 0.10417628 | K9: 0.1158636 | L9: 0.15034273 | M9: 0.12499602 | N9: 0.43759282 | O9: 0.29964427 | P9: 0.40040132 | Q9: 0.20795591 | R9: 0.37709273 | S9: 0.23020441 | T9: 0.38438647 | U9: 0.20541102 | V9: 0.22957463 | W9: 0.17637844 | X9: 0.26741696 | Y9: 0.20785382 | Z9: 0.37499995 | AA9: 0.28668283 | AB9: 0.37499997 | AC9: 0.31076971 | AD9: 0.37499998 | AE9: 0.32296855
A10: SAS | B10: 0.033814373 | C10: 0.034668232 | D10: 0.01523466 | E10: 0.015432288 | F10: 0.032427788 | G10: 0.035777343 | H10: 0.050534682 | I10: 0.032471857 | J10: 5.8905905e-07 | K10: 0.13943938 | L10: 0.37465748 | M10: 0.20170916 | N10: 0.36541931 | O10: 0.20171231 | P10: 0.32073855 | Q10: 0.19871589 | R10: 0.2976341 | S10: 0.19848523 | T10: 0.26078475 | U10: 0.25186094 | V10: 0.22631439 | W10: 0.13286062 | X10: 0.21242049 | Y10: 0.23047973 | Z10: 0.27272655 | AA10: 0.21490363 | AB10: 0.28078025 | AC10: 0.18225704 | AD10: 0.32710301 | AE10: 0.1811433
A11: PAS | B11: 0.051977513 | C11: 0.052092219 | D11: 0.0165111 | E11: 0.015998155 | F11: 0.044011746 | G11: 0.034394406 | H11: 6.4368356e-08 | I11: 0.029108598 | J11: 1.2259277e-07 | K11: 0.16918274 | L11: 0.30095546 | M11: 0.19109584 | N11: 0.28239233 | O11: 0.19109588 | P11: 0.22546121 | Q11: 0.10958905 | R11: 0.15043448 | S11: 0.11338463 | T11: 0.10958904 | U11: 0.11059736 | V11: 0.19199328 | W11: 0.12232499 | X11: 0.19430508 | Y11: 0.11165611 | Z11: 0.19109574 | AA11: 0.10482026 | AB11: 0.19905604 | AC11: 0.1002116 | AD11: 0.27739698 | AE11: 0.11459617
A12: MEA | B12: 0.033049868 | C12: 0.033281133 | D12: 0.015113725 | E12: 0.014632166 | F12: 0.074348491 | G12: 0.038798867 | H12: 0.00054643678 | I12: 0.079310541 | J12: 1.6253734e-05 | K12: 0.11643972 | L12: 0.35239726 | M12: 0.33047931 | N12: 0.31867615 | O12: 0.28527396 | P12: 0.28812188 | Q12: 0.26588389 | R12: 0.2862457 | S12: 0.25587418 | T12: 0.32646953 | U12: 0.25593981 | V12: 0.24957827 | W12: 0.25709162 | X12: 0.25723229 | Y12: 0.25609647 | Z12: 0.30190726 | AA12: 0.27195851 | AB12: 0.29320924 | AC12: 0.27526346 | AD12: 0.4020073 | AE12: 0.2685593

Sheet mc_MeOH2airfuel
B1: 2010 | C1: 2010 | D1: 2020 | E1: 2020 | F1: 2030 | G1: 2030 | H1: 2040 | I1: 2040 | J1: 2050 | K1: 2050 | L1: 2060 | M1: 2060 | N1: 2070 | O1: 2070 | P1: 2080 | Q1: 2080 | R1: 2090 | S1: 2090 | T1: 2100 | U1: 2100 | V1: 2110 | W1: 2110 | X1: 2120 | Y1: 2120 | Z1: 2130 | AA1: 2130 | AB1: 2140 | AC1: 2140 | AD1: 2150 | AE1: 2150
B2: 1 | C2: 2 | D2: 1 | E2: 2 | F2: 1 | G2: 2 | H2: 1 | I2: 2 | J2: 1 | K2: 2 | L2: 1 | M2: 2 | N2: 1 | O2: 2 | P2: 1 | Q2: 2 | R2: 1 | S2: 2 | T2: 1 | U2: 2 | V2: 1 | W2: 2 | X2: 1 | Y2: 2 | Z2: 1 | AA2: 2 | AB2: 1 | AC2: 2 | AD2: 1 | AE2: 2
A3: EUR | B3: 0 | C3: 0 | D3: 0 | E3: 0 | F3: 0 | G3: 0 | H3: 0 | I3: 0 | J3: 0 | K3: 0 | L3: 0 | M3: 0 | N3: 0 | O3: 0 | P3: 0 | Q3: 0 | R3: 0 | S3: 0 | T3: 0 | U3: 0 | V3: 0 | W3: 0 | X3: 0 | Y3: 0 | Z3: 0 | AA3: 0 | AB3: 0 | AC3: 0 | AD3: 0 | AE3: 0
A4: NAM | B4: 0 | C4: 0 | D4: 0 | E4: 0 | F4: 0 | G4: 0 | H4: 0 | I4: 0 | J4: 0 | K4: 0 | L4: 0 | M4: 0 | N4: 0 | O4: 0 | P4: 0 | Q4: 0 | R4: 0 | S4: 0 | T4: 0 | U4: 0 | V4: 0 | W4: 0 | X4: 0 | Y4: 0 | Z4: 0 | AA4: 0 | AB4: 0 | AC4: 0 | AD4: 0 | AE4: 0
A5: PAO | B5: 0 | C5: 0 | D5: 0 | E5: 0 | F5: 0 | G5: 0 | H5: 0 | I5: 0 | J5: 0 | K5: 0 | L5: 0 | M5: 0 | N5: 0 | O5: 0 | P5: 0 | Q5: 0 | R5: 0 | S5: 0 | T5: 0 | U5: 0 | V5: 0 | W5: 0 | X5: 0 | Y5: 0 | Z5: 0 | AA5: 0 | AB5: 0 | AC5: 0 | AD5: 0 | AE5: 0
A6: FSU | B6: 0 | C6: 0 | D6: 0 | E6: 0 | F6: 0 | G6: 0 | H6: 0 | I6: 0 | J6: 0 | K6: 0 | L6: 0 | M6: 0 | N6: 0 | O6: 0 | P6: 0 | Q6: 0 | R6: 0 | S6: 0 | T6: 0 | U6: 0 | V6: 0 | W6: 0 | X6: 0 | Y6: 0 | Z6: 0 | AA6: 0 | AB6: 0 | AC6: 0 | AD6: 0 | AE6: 0
A7: LAM | B7: 0 | C7: 0 | D7: 0 | E7: 0 | F7: 0 | G7: 0 | H7: 0 | I7: 0 | J7: 0 | K7: 0 | L7: 0 | M7: 0 | N7: 0 | O7: 0 | P7: 0 | Q7: 0 | R7: 0 | S7: 0 | T7: 0 | U7: 0 | V7: 0 | W7: 0 | X7: 0 | Y7: 0 | Z7: 0 | AA7: 0 | AB7: 0 | AC7: 0 | AD7: 0 | AE7: 0
A8: CPA | B8: 0 | C8: 0 | D8: 0 | E8: 0 | F8: 0 | G8: 0 | H8: 0 | I8: 0 | J8: 0 | K8: 0 | L8: 0 | M8: 0 | N8: 0 | O8: 0 | P8: 0 | Q8: 0 | R8: 0 | S8: 0 | T8: 0 | U8: 0 | V8: 0 | W8: 0 | X8: 0 | Y8: 0 | Z8: 0 | AA8: 0 | AB8: 0 | AC8: 0 | AD8: 0 | AE8: 0
A9: AFR | B9: 0 | C9: 0 | D9: 0 | E9: 0 | F9: 0 | G9: 0 | H9: 0 | I9: 0 | J9: 0 | K9: 0 | L9: 0 | M9: 0 | N9: 0 | O9: 0 | P9: 0 | Q9: 0 | R9: 0 | S9: 0 | T9: 0 | U9: 0 | V9: 0 | W9: 0 | X9: 0 | Y9: 0 | Z9: 0 | AA9: 0 | AB9: 0 | AC9: 0 | AD9: 0 | AE9: 0
A10: SAS | B10: 0 | C10: 0 | D10: 0 | E10: 0 | F10: 0 | G10: 0 | H10: 0 | I10: 0 | J10: 0 | K10: 0 | L10: 0 | M10: 0 | N10: 0 | O10: 0 | P10: 0 | Q10: 0 | R10: 0 | S10: 0 | T10: 0 | U10: 0 | V10: 0 | W10: 0 | X10: 0 | Y10: 0 | Z10: 0 | AA10: 0 | AB10: 0 | AC10: 0 | AD10: 0 | AE10: 0
A11: PAS | B11: 0 | C11: 0 | D11: 0 | E11: 0 | F11: 0 | G11: 0 | H11: 0 | I11: 0 | J11: 0 | K11: 0 | L11: 0 | M11: 0 | N11: 0 | O11: 0 | P11: 0 | Q11: 0 | R11: 0 | S11: 0 | T11: 0 | U11: 0 | V11: 0 | W11: 0 | X11: 0 | Y11: 0 | Z11: 0 | AA11: 0 | AB11: 0 | AC11: 0 | AD11: 0 | AE11: 0
A12: MEA | B12: 0 | C12: 0 | D12: 0 | E12: 0 | F12: 0 | G12: 0 | H12: 0 | I12: 0 | J12: 0 | K12: 0 | L12: 0 | M12: 0 | N12: 0 | O12: 0 | P12: 0 | Q12: 0 | R12: 0 | S12: 0 | T12: 0 | U12: 0 | V12: 0 | W12: 0 | X12: 0 | Y12: 0 | Z12: 0 | AA12: 0 | AB12: 0 | AC12: 0 | AD12: 0 | AE12: 0

Sheet mc_carbon_budget
A1: 1 | B1: 2
A2: 557968.3 | B2: 557968.3

Sheet mc_liquids_2050
B1: 1 | C1: 2
A2: oil | B2: 0 | C2: 0
A3: coal | B3: 5.0682 | C3: 5.0682
A4: MeOH | B4: 7.6289443 | C4: 27.574232
A5: H2 | B5: 0 | C5: 0
A6: elec | B6: 44.811313 | C6: 43.684518
A7: petro | B7: 113.2407 | C7: 97.671605
A8: CH4 | B8: 5.0682 | C8: 5.0682
A9: LCH4 | B9: 3.1106524e-08 | C9: 1.0811845
A10: LH2 | B10: 5.5959865e-08 | C10: 2.2642095e-08
A11: CH2 | B11: 0.015300932 | C11: 0.015300885

Sheet liquids graf
B1: 1 | C1: 2 | D1: 3 | E1: 4 | F1: 5 | G1: 6 | H1: 7 | I1: 8 | J1: 9 | K1: 10 | L1: 11 | M1: 12 | N1: 13 | O1: 14 | P1: 15 | Q1: 16 | R1: 17 | S1: 18 | T1: 19 | U1: 20 | V1: 21 | W1: 22 | X1: 23 | Y1: 24 | Z1: 25 | AA1: 26 | AB1: 27 | AC1: 28 | AD1: 29 | AE1: 30 | AF1: 31 | AG1: 32 | AH1: 33 | AI1: 34 | AJ1: 35 | AK1: 36 | AL1: 37 | AM1: 38 | AN1: 39 | AO1: 40 | AP1: 41 | AQ1: 42 | AR1: 43 | AS1: 44 | AT1: 45 | AU1: 46 | AV1: 47 | AW1: 48 | AX1: 49 | AY1: 50 | AZ1: 51 | BA1: 52 | BB1: 53 | BC1: 54 | BD1: 55 | BE1: 56 | BF1: 57 | BG1: 58 | BH1: 59 | BI1: 60 | BJ1: 61 | BK1: 62 | BL1: 63 | BM1: 64 | BN1: 65 | BO1: 66 | BP1: 67 | BQ1: 68 | BR1: 69 | BS1: 70 | BT1: 71 | BU1: 72 | BV1: 73 | BW1: 74 | BX1: 75 | BY1: 76 | BZ1: 77 | CA1: 78 | CB1: 79 | CC1: 80 | CD1: 81 | CE1: 82 | CF1: 83 | CG1: 84 | CH1: 85 | CI1: 86 | CJ1: 87 | CK1: 88 | CL1: 89 | CM1: 90 | CN1: 91 | CO1: 92 | CP1: 93 | CQ1: 94 | CR1: 95 | CS1: 96 | CT1: 97 | CU1: 98 | CV1: 99 | CW1: 100 | CX1: 101 | CY1: 102 | CZ1: 103 | DA1: 104 | DB1: 105 | DC1: 106 | DD1: 107 | DE1: 108 | DF1: 109 | DG1: 110 | DH1: 111 | DI1: 112 | DJ1: 113 | DK1: 114 | DL1: 115 | DM1: 116 | DN1: 117 | DO1: 118 | DP1: 119 | DQ1: 120 | DR1: 121 | DS1: 122 | DT1: 123 | DU1: 124 | DV1: 125 | DW1: 126 | DX1: 127 | DY1: 128 | DZ1: 129 | EA1: 130 | EB1: 131 | EC1: 132 | ED1: 133 | EE1: 134 | EF1: 135 | EG1: 136 | EH1: 137 | EI1: 138 | EJ1: 139 | EK1: 140 | EL1: 141 | EM1: 142 | EN1: 143 | EO1: 144 | EP1: 145 | EQ1: 146 | ER1: 147 | ES1: 148 | ET1: 149 | EU1: 150 | EV1: 151 | EW1: 152 | EX1: 153 | EY1: 154 | EZ1: 155 | FA1: 156 | FB1: 157 | FC1: 158 | FD1: 159 | FE1: 160 | FF1: 161 | FG1: 162 | FH1: 163 | FI1: 164 | FJ1: 165 | FK1: 166 | FL1: 167 | FM1: 168 | FN1: 169 | FO1: 170 | FP1: 171 | FQ1: 172 | FR1: 173 | FS1: 174 | FT1: 175 | FU1: 176 | FV1: 177 | FW1: 178 | FX1: 179 | FY1: 180 | FZ1: 181 | GA1: 182 | GB1: 183 | GC1: 184 | GD1: 185 | GE1: 186 | GF1: 187 | GG1: 188 | GH1: 189 | GI1: 190 | GJ1: 191 | GK1: 192 | GL1: 193 | GM1: 194 | GN1: 195 | GO1: 196 | GP1: 197 | GQ1: 198 | GR1: 199 | GS1: 200 | GT1: 201 | GU1: 202 | GV1: 203 | GW1: 204 | GX1: 205 | GY1: 206 | GZ1: 207 | HA1: 208 | HB1: 209 | HC1: 210 | HD1: 211 | HE1: 212 | HF1: 213 | HG1: 214 | HH1: 215 | HI1: 216 | HJ1: 217 | HK1: 218 | HL1: 219 | HM1: 220 | HN1: 221 | HO1: 222 | HP1: 223 | HQ1: 224 | HR1: 225 | HS1: 226 | HT1: 227 | HU1: 228 | HV1: 229 | HW1: 230 | HX1: 231 | HY1: 232 | HZ1: 233 | IA1: 234 | IB1: 235 | IC1: 236 | ID1: 237 | IE1: 238 | IF1: 239 | IG1: 240 | IH1: 241 | II1: 242 | IJ1: 243 | IK1: 244 | IL1: 245 | IM1: 246 | IN1: 247 | IO1: 248 | IP1: 249 | IQ1: 250 | IR1: 251 | IS1: 252 | IT1: 253 | IU1: 254 | IV1: 255 | IW1: 256 | IX1: 257 | IY1: 258 | IZ1: 259 | JA1: 260 | JB1: 261 | JC1: 262 | JD1: 263 | JE1: 264 | JF1: 265 | JG1: 266 | JH1: 267 | JI1: 268 | JJ1: 269 | JK1: 270 | JL1: 271 | JM1: 272 | JN1: 273 | JO1: 274 | JP1: 275 | JQ1: 276 | JR1: 277 | JS1: 278 | JT1: 279 | JU1: 280 | JV1: 281 | JW1: 282 | JX1: 283 | JY1: 284 | JZ1: 285 | KA1: 286 | KB1: 287 | KC1: 288 | KD1: 289 | KE1: 290 | KF1: 291 | KG1: 292 | KH1: 293 | KI1: 294 | KJ1: 295 | KK1: 296 | KL1: 297 | KM1: 298 | KN1: 299 | KO1: 300 | KP1: 301 | KQ1: 302 | KR1: 303 | KS1: 304 | KT1: 305 | KU1: 306 | KV1: 307 | KW1: 308 | KX1: 309 | KY1: 310 | KZ1: 311 | LA1: 312 | LB1: 313 | LC1: 314 | LD1: 315 | LE1: 316 | LF1: 317 | LG1: 318 | LH1: 319 | LI1: 320 | LJ1: 321 | LK1: 322 | LL1: 323 | LM1: 324 | LN1: 325 | LO1: 326 | LP1: 327 | LQ1: 328 | LR1: 329 | LS1: 330 | LT1: 331 | LU1: 332 | LV1: 333 | LW1: 334 | LX1: 335 | LY1: 336 | LZ1: 337 | MA1: 338 | MB1: 339 | MC1: 340 | MD1: 341 | ME1: 342 | MF1: 343 | MG1: 344 | MH1: 345 | MI1: 346 | MJ1: 347 | MK1: 348 | ML1: 349 | MM1: 350 | MN1: 351 | MO1: 352 | MP1: 353 | MQ1: 354 | MR1: 355 | MS1: 356 | MT1: 357 | MU1: 358 | MV1: 359 | MW1: 360 | MX1: 361 | MY1: 362 | MZ1: 363 | NA1: 364 | NB1: 365 | NC1: 366 | ND1: 367 | NE1: 368 | NF1: 369 | NG1: 370 | NH1: 371 | NI1: 372 | NJ1: 373 | NK1: 374 | NL1: 375 | NM1: 376 | NN1: 377 | NO1: 378 | NP1: 379 | NQ1: 380 | NR1: 381 | NS1: 382 | NT1: 383 | NU1: 384 | NV1: 385 | NW1: 386 | NX1: 387 | NY1: 388 | NZ1: 389 | OA1: 390
A2: Oil based fuels | B2: =mc_liquids_2050!B2+mc_liquids_2050!B7 -> 113.2407 | C2: =mc_liquids_2050!C2+mc_liquids_2050!C7 -> 97.671605 | D2: =mc_liquids_2050!D2+mc_liquids_2050!D7 -> 0 | E2: =mc_liquids_2050!E2+mc_liquids_2050!E7 -> 0 | F2: =mc_liquids_2050!F2+mc_liquids_2050!F7 -> 0 | G2: =mc_liquids_2050!G2+mc_liquids_2050!G7 -> 0 | H2: =mc_liquids_2050!H2+mc_liquids_2050!H7 -> 0 | I2: =mc_liquids_2050!I2+mc_liquids_2050!I7 -> 0 | ... OA2: =mc_liquids_2050!OA2+mc_liquids_2050!OA7 -> 0
A3: Synfuels | B3: =mc_liquids_2050!B4 -> 7.6289443 | C3: =mc_liquids_2050!C4 -> 27.574232 | D3: =mc_liquids_2050!D4 -> 0 | E3: =mc_liquids_2050!E4 -> 0 | F3: =mc_liquids_2050!F4 -> 0 | G3: =mc_liquids_2050!G4 -> 0 | H3: =mc_liquids_2050!H4 -> 0 | I3: =mc_liquids_2050!I4 -> 0 | ... OA3: =mc_liquids_2050!OA4 -> 0
A4: H2 | B4: =mc_liquids_2050!B5 -> 0 | C4: =mc_liquids_2050!C5 -> 0 | D4: =mc_liquids_2050!D5 -> 0 | E4: =mc_liquids_2050!E5 -> 0 | F4: =mc_liquids_2050!F5 -> 0 | G4: =mc_liquids_2050!G5 -> 0 | H4: =mc_liquids_2050!H5 -> 0 | I4: =mc_liquids_2050!I5 -> 0 | ... OA4: =mc_liquids_2050!OA5 -> 0
A5: elec | B5: =mc_liquids_2050!B6 -> 44.811313 | C5: =mc_liquids_2050!C6 -> 43.684518 | D5: =mc_liquids_2050!D6 -> 0 | E5: =mc_liquids_2050!E6 -> 0 | F5: =mc_liquids_2050!F6 -> 0 | G5: =mc_liquids_2050!G6 -> 0 | H5: =mc_liquids_2050!H6 -> 0 | I5: =mc_liquids_2050!I6 -> 0 | ... OA5: =mc_liquids_2050!OA6 -> 0
A6: CNG or LNG | B6: =mc_liquids_2050!B8 -> 5.0682 | C6: =mc_liquids_2050!C8 -> 5.0682 | D6: =mc_liquids_2050!D8 -> 0 | E6: =mc_liquids_2050!E8 -> 0 | F6: =mc_liquids_2050!F8 -> 0 | G6: =mc_liquids_2050!G8 -> 0 | H6: =mc_liquids_2050!H8 -> 0 | I6: =mc_liquids_2050!I8 -> 0 | ... OA6: =mc_liquids_2050!OA8 -> 0

Sheet mc_meohfeed_2050
B1: 1 | C1: 2
A2: oil1 | B2: 0 | C2: 0
A3: oil2 | B3: 0 | C3: 0
A4: oil3 | B4: 0 | C4: 0
A5: bio | B5: 1.5839537 | C5: 41.947883
A6: bio1 | B6: 0 | C6: 0
A7: bio2 | B7: 0 | C7: 0
A8: bio3 | B8: 0 | C8: 0
A9: hydro | B9: 0 | C9: 0
A10: wind | B10: 0 | C10: 0
A11: solar | B11: 0 | C11: 0
A12: gas1 | B12: 0 | C12: 0
A13: gas2 | B13: 0 | C13: 0
... A63: CH2 | B63: 0 | C63: 0

Sheet mc_h2feed_2050
B1: 1 | C1: 2 | D1: 3 | E1: 4 | F1: 5
A2: oil1 | B2: 0 | C2: 0 | D2: 0 | E2: 0 | F2: 0
A3: oil2 | B3: 0 | C3: 0 | D3: 0 | E3: 0 | F3: 0
A4: oil3 | B4: 0 | C4: 0 | D4: 0 | E4: 0 | F4: 0
A5: bio | B5: 18.935587 | C5: 22.160205 | D5: 0.12223433 | E5: 2.3957234 | F5: 13.903775
A6: bio1 | B6: 0 | C6: 0 | D6: 0 | E6: 0 | F6: 0
A7: bio2 | B7: 0 | C7: 0 | D7: 0 | E7: 0 | F7: 0
A8: bio3 | B8: 0 | C8: 0 | D8: 0 | E8: 0 | F8: 0
A9: hydro | B9: 0 | C9: 0 | D9: 0 | E9: 0 | F9: 0
A10: wind | B10: 0 | C10: 0 | D10: 0 | E10: 0 | F10: 0
A11: solar | B11: 2.4872891e-07 | C11: 2.6927726e-07 | D11: 1.5008764 | E11: 3.5278027e-06 | F11: 3.9202965e-08
A12: gas1 | B12: 0 | C12: 0 | D12: 0 | E12: 0 | F12: 0
A13: gas2 | B13: 0 | C13: 0 | D13: 0 | E13: 0 | F13: 0
... A60: NH3 | B60: 0 | C60: 0 | D60: 0 | E60: 0 | F60: 0

Sheet Sheet1
A1: Runs
